Workbook
Name Fafi: #REF!
Name Dadaab: #REF!
Name Lagdera: #REF!
Name GarissaTownship: #REF!
Name Balambala: #REF!
Name Ijara: #REF!

Sheet instructions1
A1: INSTRUCTIONS ON COMPLETION OF PROJECT STOCK TAKE TEMPLATE
A2: 1. All fields are mandatory and should be populated.
A3: 2. DO NOT EDIT the CONFIGURATION worksheet.
A4: 3. ONLY populate rows applicable in your respective Counties &Ward Location(s) and Hide the rest of the rows (DO NOT DELETE the Rows).
A5: 4. The scope of this exercise is projects started between the year 2013 and 30th June, 2024
A6: 5.Remember to SAVE the document after populating the required details in the worksheet.

Sheet Project Stocktaking Template
A1: PROJECT DETAILS | H1: PROJECT LOCATION | K1: IMPLEMENTATION DETAILS | R1: FINANCIAL INFORMATION | W1: DISBURSMENT | AA1: EXPENDITURE | AD1: PROJECT STATUS | AG1: ACTIONS FOR STALLED | AK1: RISKS AND RECOMMENDATIONS | AN1: CLIMATE & DISASTER RISK SCREENING | AP1: ENVIRONMENTAL , SOCIAL AND OCCUPATIONAL HEALTH, SAFETY AND GENDER SCREENING | AR1: TECHNICAL, FINANCIAL, AND ECONOMIC VIABILITY SCREENING | AT1: ADDITIONAL REMARKS
A2: S/No. | B2: Project Name/Title | C2: Project Description | D2: Project Goal/Objective | E2: Project Output | F2: Project Code (Budget line) | G2: Budget Item Name | H2: Sub-County | I2: Ward | J2: Geographic Location (Latitude & Longitude) | K2: Sector/ Vote Name | L2: Department, Directorate, Units, Agencies | M2: Implementing Department/Agency / Muncipalities | N2: Date of Approval/Financial Approval | O2: Project Start Date | P2: Expected Project Completion Date | Q2: Actual Project Completion Date | R2: Estimated Project Cost (Kshs.) | S2: Approved Project Cost | T2: Funds available in the specific year | U2: Project Funding Source | V2: If Development Partners, Please specify . | W2: County Government component in the Project Cost (Kshs.) | X2: Development Partner component in the Project Cost (Kshs.) | Y2: Total Disbursed Funds as at 30th June 2024 (Kshs.) | Z2: Percentage (%) Disbursed Amount = (Disbursed/ Approved) | AA2: Expenditure to date | AB2: Pending Bill/Outstanding commitment not paid but work done | AC2: Project Balance (Kshs.) i.e (Approved Project Cost - Disbursed Amount) | AD2: Project Status at the time of the Exercise (i.e Completed, Ongoing, Stalled) | AE2: % completion for ongoing/stalled projects | AF2: If Stalled, what is the percentage (%) completion at the time of stalling (Physical completion status) | AG2: If stalled give reasons; | AH2: Year the project stalled | AI2: Time required to complete the stalled project (in months) | AJ2: Estimated cost required to complete the stalled project (in Kshs.) | AK2: Is the project still appering in the budget or is it still receiving funds in the annual budgets? (Yes/No) | AL2: Recommendation for the Stalled Project (Complete/ Cancel/ Defer) | AM2: Identify the Risks associated with the stalled/completed/ongoing project ie. (Contractual/legal/Financial/Environmental etc.) | AN2: Has this project been screened for Climate & Disaster Risks? Yes/No | AO2: If yes, what action has been taken to mitigate? IF Not, give reasons and the immediate plans for conducting the screening. | AP2: Has the project been screened for Environmental, Social, Occupational Health, Safety and gender risks | AQ2: If yes, what action has been taken to mitigate? IF Not, give reasons and the immediate plans for conducting the screening. | AR2: Has the project been screened for Technical, Financial, and Economic Viability and a fesibility report been prepared? (yes/No) | AS2: If yes, what action has been taken to mitigate? IF Not, what is being used to measure viability of the project? Additionally, indicate immediate plans on when the screening and feasibility study will be undertaken | AT2: REMARKS
A3: 1 | B3: PROPOSED POWER UPGRADE AT GARISSA REFERAL HOSPITAL Waberi | H3: GarissaTownship | I3: Township | K3: =L3 -> Health services | L3: Health services | M3: =L3 -> Health services | N3: 1st july 2022 | O3: 1st aug 2022 | P3: 30th june 2023 | Q3: 30th june 2023 | R3: 8550000 | S3: 8550000 | T3: 8550000 | U3: CGG | W3: 8550000 | Y3: 8550000 | Z3: =Y3/T3 -> 1 | AA3: 8550000 | AC3: =S3-Y3 -> 0 | AD3: Completed
A4: 2 | B4: PROPOSED DRILLINGAND EQUIPPING OF ADC FARM BOREHOLE | H4: GarissaTownship | I4: Galbet | K4: =L4 -> WATER,ENVIRONMENT,CLIMATE CHANGE AND NATURAL RESOURCES | L4: WATER,ENVIRONMENT,CLIMATE CHANGE AND NATURAL RESOURCES | M4: =L4 -> WATER,ENVIRONMENT,CLIMATE CHANGE AND NATURAL RESOURCES | N4: 1st july 2022 | O4: 1st aug 2022 | P4: 30th june 2023 | Q4: 30th june 2023 | R4: 9025000 | S4: 9025000 | T4: 9025000 | U4: CGG | W4: 9025000 | Y4: 9025000 | Z4: =Y4/T4 -> 1 | AA4: 9025000 | AC4: =S4-Y4 -> 0 | AD4: Completed
A5: 3 | B5: PROPOSED EQUIPING OF DERTU BOREHOLE | H5: Dadaab | I5: Dertu | K5: =L5 -> WATER,ENVIRONMENT,CLIMATE CHANGE AND NATURAL RESOURCES | L5: WATER,ENVIRONMENT,CLIMATE CHANGE AND NATURAL RESOURCES | M5: =L5 -> WATER,ENVIRONMENT,CLIMATE CHANGE AND NATURAL RESOURCES | N5: 1st july 2022 | O5: 1st aug 2022 | P5: 30th june 2023 | Q5: 30th june 2023 | R5: 4625407 | S5: 4625407 | T5: 4625407 | U5: CGG | W5: 4625407 | Y5: 4625407 | Z5: =Y5/T5 -> 1 | AA5: 4625407 | AC5: =S5-Y5 -> 0 | AD5: Completed
A6: 4 | B6: PROPOSED DRILLING OF DERTU BOREHOLE | H6: Dadaab | I6: Dertu | K6: =L6 -> WATER,ENVIRONMENT,CLIMATE CHANGE AND NATURAL RESOURCES | L6: WATER,ENVIRONMENT,CLIMATE CHANGE AND NATURAL RESOURCES | M6: =L6 -> WATER,ENVIRONMENT,CLIMATE CHANGE AND NATURAL RESOURCES | N6: 1st july 2022 | O6: 1st aug 2022 | P6: 30th june 2023 | Q6: 30th june 2023 | R6: 4693418 | S6: 4693418 | T6: 4693418 | U6: CGG | W6: 4693418 | Y6: 4693418 | Z6: =Y6/T6 -> 1 | AA6: 4693418 | AC6: =S6-Y6 -> 0 | AD6: Completed
A7: 5 | B7: PROPOSED DESILTING AT MOIT WATER PAN IJARA SUB COUNTY | H7: Ijara | I7: Ijara | K7: =L7 -> WATER,ENVIRONMENT,CLIMATE CHANGE AND NATURAL RESOURCES | L7: WATER,ENVIRONMENT,CLIMATE CHANGE AND NATURAL RESOURCES | M7: =L7 -> WATER,ENVIRONMENT,CLIMATE CHANGE AND NATURAL RESOURCES | N7: 1st july 2022 | O7: 1st aug 2022 | P7: 30th june 2023 | Q7: 30th june 2023 | R7: 3482500 | S7: 3482500 | T7: 3482500 | U7: CGG | W7: 3482500 | Y7: 3482500 | Z7: =Y7/T7 -> 1 | AA7: 3482500 | AC7: =S7-Y7 -> 0 | AD7: Completed
A8: 6 | B8: PROPOSED RENOVATION OF 4NO ECD CLASSROOM AT MAI PRIMARY | H8: Ijara | I8: Masalani | K8: =L8 -> EDUCATION,INFORMATION AND ICT | L8: EDUCATION,INFORMATION AND ICT | M8: =L8 -> EDUCATION,INFORMATION AND ICT | N8: 1st july 2022 | O8: 1st aug 2022 | P8: 30th june 2023 | Q8: 30th june 2023 | R8: 3100000 | S8: 3100000 | T8: 3100000 | U8: CGG | W8: 3100000 | Y8: 3100000 | Z8: =Y8/T8 -> 1 | AA8: 3100000 | AC8: =S8-Y8 -> 0 | AD8: Completed
A9: 7 | B9: PROPOSED RENOVATION OF 3NO. ECD CLASSROOMS CONSTRUCTION OF 2 STANCE PIT LATRINE RENOVATION OF 10K WATER TANK AT YATHRIB PRIMARY | H9: GarissaTownship | I9: Galbet | K9: =L9 -> EDUCATION,INFORMATION AND ICT | L9: EDUCATION,INFORMATION AND ICT | M9: =L9 -> EDUCATION,INFORMATION AND ICT | N9: 1st july 2022 | O9: 1st aug 2022 | P9: 30th june 2023 | Q9: 30th june 2023 | R9: 7200000 | S9: 7200000 | T9: 7200000 | U9: CGG | W9: 7200000 | Y9: 7200000 | Z9: =Y9/T9 -> 1 | AA9: 7200000 | AC9: =S9-Y9 -> 0 | AD9: Completed
A10: 8 | B10: PROPOSED RENOVATION OF 3NO. ECD CLASSROOMS CONSTRUCTION OF CHAINLINK FENCE AND HEAVY BUSH CLEARING2 STANCE PIT LATRINE RENOVATION K AT IFTIN PRIMARY | H10: GarissaTownship | I10: Iftin | K10: =L10 -> EDUCATION,INFORMATION AND ICT | L10: EDUCATION,INFORMATION AND ICT | M10: =L10 -> EDUCATION,INFORMATION AND ICT | N10: 1st july 2022 | O10: 1st aug 2022 | P10: 30th june 2023 | Q10: 30th june 2023 | R10: 5225000 | S10: 5225000 | T10: 5225000 | U10: CGG | W10: 5225000 | Y10: 5225000 | Z10: =Y10/T10 -> 1 | AA10: 5225000 | AC10: =S10-Y10 -> 0 | AD10: Completed
A11: 9 | B11: PROPOSED RENOVATION OF 3NO. ECD CLASSROOMS CONSTRUCTION OF 2 STANCE PIT LATRINE RENOVATION OF 10K WATER TANK AT AP GOODWISH TOWNSHIP WARD | H11: GarissaTownship | I11: Township | K11: =L11 -> EDUCATION,INFORMATION AND ICT | L11: EDUCATION,INFORMATION AND ICT | M11: =L11 -> EDUCATION,INFORMATION AND ICT | N11: 1st july 2022 | O11: 1st aug 2022 | P11: 30th june 2023 | Q11: 30th june 2023 | R11: 5225000 | S11: 5225000 | T11: 5225000 | U11: CGG | W11: 5225000 | Y11: 5225000 | Z11: =Y11/T11 -> 1 | AA11: 5225000 | AC11: =S11-Y11 -> 0 | AD11: Completed
A12: 10 | B12: PROPOSED RENOVATION 2NO ECD CLASSROOMS AND HEAVY BUSH CLEARING AND FENCING AT BULA MZURI PRIMARY | H12: GarissaTownship | I12: Waberi | K12: =L12 -> EDUCATION,INFORMATION AND ICT | L12: EDUCATION,INFORMATION AND ICT | M12: =L12 -> EDUCATION,INFORMATION AND ICT | N12: 1st july 2022 | O12: 1st aug 2022 | P12: 30th june 2023 | Q12: 30th june 2023 | R12: 5225000 | S12: 5225000 | T12: 5225000 | U12: CGG | W12: 5225000 | Y12: 5225000 | Z12: =Y12/T12 -> 1 | AA12: 5225000 | AC12: =S12-Y12 -> 0 | AD12: Completed
A13: 11 | B13: PRPOSED RENOVATION OF AND ROOFING AT WATER GARAGE GARISSA COUNTY | H13: GarissaTownship | I13: Township | K13: =L13 -> WATER,ENVIRONMENT,CLIMATE CHANGE AND NATURAL RESOURCES | L13: WATER,ENVIRONMENT,CLIMATE CHANGE AND NATURAL RESOURCES | M13: =L13 -> WATER,ENVIRONMENT,CLIMATE CHANGE AND NATURAL RESOURCES | N13: 1st july 2022 | O13: 1st aug 2022 | P13: 30th june 2023 | Q13: 30th june 2023 | R13: 7600000 | S13: 7600000 | T13: 7600000 | U13: CGG | W13: 7600000 | Y13: 7600000 | Z13: =Y13/T13 -> 1 | AA13: 7600000 | AC13: =S13-Y13 -> 0 | AD13: Completed
A14: 12 | B14: PRPOSED RENOVATION OF AND ROOFING AT WATER GARAGE GARISSA COUNTY | H14: GarissaTownship | I14: Township | K14: =L14 -> WATER,ENVIRONMENT,CLIMATE CHANGE AND NATURAL RESOURCES | L14: WATER,ENVIRONMENT,CLIMATE CHANGE AND NATURAL RESOURCES | M14: =L14 -> WATER,ENVIRONMENT,CLIMATE CHANGE AND NATURAL RESOURCES | N14: 1st july 2022 | O14: 1st aug 2022 | P14: 30th june 2023 | Q14: 30th june 2023 | R14: 7990000 | S14: 7990000 | T14: 7990000 | U14: CGG | W14: 7990000 | Y14: 7990000 | Z14: =Y14/T14 -> 1 | AA14: 7990000 | AC14: =S14-Y14 -> 0 | AD14: Completed
A15: 13 | B15: PROPOSED RENOVATION AND REFURBISHMENT OF DIRECTORS OFFICE | H15: GarissaTownship | I15: Township | K15: =L15 | M15: =L15 | N15: 1st july 2022 | O15: 1st aug 2022 | P15: 30th june 2023 | Q15: 30th june 2023 | R15: 1470000 | S15: 1470000 | T15: 1470000 | U15: CGG | W15: 1470000 | Y15: 1470000 | Z15: =Y15/T15 -> 1 | AA15: 1470000 | AC15: =S15-Y15 -> 0 | AD15: Completed
A16: 14 | B16: RENOVATION OF CEC OFFICES | H16: GarissaTownship | I16: Township | K16: =L16 | M16: =L16 | N16: 1st july 2022 | O16: 1st aug 2022 | P16: 30th june 2023 | Q16: 30th june 2023 | R16: 1000000 | S16: 1000000 | T16: 1000000 | U16: CGG | W16: 1000000 | Y16: 1000000 | Z16: =Y16/T16 -> 1 | AA16: 1000000 | AC16: =S16-Y16 -> 0 | AD16: Completed
A17: 15 | B17: PRPOSED RENOVATION OF AND ROOFING AT WATER GARAGE GARISSA COUNTY | H17: GarissaTownship | I17: Township | K17: =L17 -> WATER,ENVIRONMENT,CLIMATE CHANGE AND NATURAL RESOURCES | L17: WATER,ENVIRONMENT,CLIMATE CHANGE AND NATURAL RESOURCES | M17: =L17 -> WATER,ENVIRONMENT,CLIMATE CHANGE AND NATURAL RESOURCES | N17: 1st july 2022 | O17: 1st aug 2022 | P17: 30th june 2023 | Q17: 30th june 2023 | R17: 7990000 | S17: 7990000 | T17: 7990000 | U17: CGG | W17: 7990000 | Y17: 7990000 | Z17: =Y17/T17 -> 1 | AA17: 7990000 | AC17: =S17-Y17 -> 0 | AD17: Completed
A18: 16 | B18: PROPOSED REHABILATATION WORKS AT GAWASCO PIPE WORKS | H18: GarissaTownship | I18: Township | K18: =L18 -> WATER,ENVIRONMENT,CLIMATE CHANGE AND NATURAL RESOURCES | L18: WATER,ENVIRONMENT,CLIMATE CHANGE AND NATURAL RESOURCES | M18: =L18 -> WATER,ENVIRONMENT,CLIMATE CHANGE AND NATURAL RESOURCES | N18: 1st july 2022 | O18: 1st aug 2022 | P18: 30th june 2023 | Q18: 30th june 2023 | R18: 3895000 | S18: 3895000 | T18: 3895000 | U18: CGG | W18: 3895000 | Y18: 3895000 | Z18: =Y18/T18 -> 1 | AA18: 3895000 | AC18: =S18-Y18 -> 0 | AD18: Completed
A19: 17 | B19: PROPOSED RENOVATION AT DADAAB SUB COUNTY HOSPITAL | H19: Dadaab | I19: Dadaab | K19: =L19 -> Health services | L19: Health services | M19: =L19 -> Health services | N19: 1st july 2022 | O19: 1st aug 2022 | P19: 30th june 2023 | Q19: 30th june 2023 | R19: 3325000 | S19: 3325000 | T19: 3325000 | U19: CGG | W19: 3325000 | Y19: 3325000 | Z19: =Y19/T19 -> 1 | AA19: 3325000 | AC19: =S19-Y19 -> 0 | AD19: Completed
A20: 18 | B20: PROPOSED RENOVATION OF 4NO ECD CLASSROOMS AT DIHLENUR PRIMARY SCHOOL | H20: GarissaTownship | I20: Township | K20: =L20 -> EDUCATION,INFORMATION AND ICT | L20: EDUCATION,INFORMATION AND ICT | M20: =L20 -> EDUCATION,INFORMATION AND ICT | N20: 1st july 2022 | O20: 1st aug 2022 | P20: 30th june 2023 | Q20: 30th june 2023 | R20: 4687852 | S20: 4687852 | T20: 4687852 | U20: CGG | W20: 4687852 | Y20: 4687852 | Z20: =Y20/T20 -> 1 | AA20: 4687852 | AC20: =S20-Y20 -> 0 | AD20: Completed
A21: 19 | B21: PROPOSED RENOVATION AT GARISSA FIRE STATION | H21: GarissaTownship | I21: Township | K21: =L21 -> LANDS,PHYSICAL PLANNING AND URBAN DEVELOPMENT | L21: LANDS,PHYSICAL PLANNING AND URBAN DEVELOPMENT | M21: =L21 -> LANDS,PHYSICAL PLANNING AND URBAN DEVELOPMENT | N21: 1st july 2022 | O21: 1st aug 2022 | P21: 30th june 2023 | Q21: 30th june 2023 | R21: 4750000 | S21: 4750000 | T21: 4750000 | U21: CGG | W21: 4750000 | Y21: 4750000 | Z21: =Y21/T21 -> 1 | AA21: 4750000 | AC21: =S21-Y21 -> 0 | AD21: Completed
A22: 20 | B22: PROPOSED FENCING AND PIT LATRINE AT MASALANI LIVESTOCK OFFICE | H22: Ijara | I22: Masalani | K22: =L22 -> AGRICULTURE,LIVESTOCK AND PASTORAL ECONOMY | L22: AGRICULTURE,LIVESTOCK AND PASTORAL ECONOMY | M22: =L22 -> AGRICULTURE,LIVESTOCK AND PASTORAL ECONOMY | N22: 1st july 2022 | O22: 1st aug 2022 | P22: 30th june 2023 | Q22: 30th june 2023 | R22: 3309210 | S22: 3309210 | T22: 3309210 | U22: CGG | W22: 3309210 | Y22: 3309210 | Z22: =Y22/T22 -> 1 | AA22: 3309210 | AC22: =S22-Y22 -> 0 | AD22: Completed
A23: 21 | B23: PROPOSED RENOVATION AND REFURBISHMENT OF COUNTY HQ | H23: GarissaTownship | I23: Township | K23: =L23 -> COUNTY AFFAIRS,PUBLIC SERVICES AND INTERGOVERNMENTAL RELATIONS | L23: COUNTY AFFAIRS,PUBLIC SERVICES AND INTERGOVERNMENTAL RELATIONS | M23: =L23 -> COUNTY AFFAIRS,PUBLIC SERVICES AND INTERGOVERNMENTAL RELATIONS | N23: 1st july 2022 | O23: 1st aug 2022 | P23: 30th june 2023 | Q23: 30th june 2023 | R23: 1425000 | S23: 1425000 | T23: 1425000 | U23: CGG | W23: 1425000 | Y23: 1425000 | Z23: =Y23/T23 -> 1 | AA23: 1425000 | AC23: =S23-Y23 -> 0 | AD23: Completed
A24: 22 | B24: PROPOSED DRILLING AND DEVELOPMENT OF BOREHOLE ASSOCIATED WORKS AT KONE MODOGASHE | H24: Balambala | I24: Balambala | K24: =L24 -> WATER,ENVIRONMENT,CLIMATE CHANGE AND NATURAL RESOURCES | L24: WATER,ENVIRONMENT,CLIMATE CHANGE AND NATURAL RESOURCES | M24: =L24 -> WATER,ENVIRONMENT,CLIMATE CHANGE AND NATURAL RESOURCES | N24: 1st july 2022 | O24: 1st aug 2022 | P24: 30th june 2023 | Q24: 30th june 2023 | R24: 19000000 | S24: 19000000 | T24: 19000000 | U24: CGG | W24: 19000000 | Y24: 19000000 | Z24: =Y24/T24 -> 1 | AA24: 19000000 | AC24: =S24-Y24 -> 0 | AD24: Completed
A25: 23 | B25: PROPOSED RENOVATION OF AGRICULTURE AND LIVESTOCK OFFICE IN MASALANI | H25: Ijara | I25: Masalani | K25: =L25 -> AGRICULTURE,LIVESTOCK AND PASTORAL ECONOMY | L25: AGRICULTURE,LIVESTOCK AND PASTORAL ECONOMY | M25: =L25 -> AGRICULTURE,LIVESTOCK AND PASTORAL ECONOMY | N25: 1st july 2022 | O25: 1st aug 2022 | P25: 30th june 2023 | Q25: 30th june 2023 | R25: 4111317 | S25: 4111317 | T25: 4111317 | U25: CGG | W25: 4111317 | Y25: 4111317 | Z25: =Y25/T25 -> 1 | AA25: 4111317 | AC25: =S25-Y25 -> 0 | AD25: Completed
A26: 24 | B26: PROPOSED RENOVATION OF COUNTY COUNCIL OFFICE | H26: GarissaTownship | I26: Township | K26: =L26 -> ROADS,TRANSPORT AND PUBLIC WORKS | L26: ROADS,TRANSPORT AND PUBLIC WORKS | M26: =L26 -> ROADS,TRANSPORT AND PUBLIC WORKS | N26: 1st july 2022 | O26: 1st aug 2022 | P26: 30th june 2023 | Q26: 30th june 2023 | R26: 2375000 | S26: 2375000 | T26: 2375000 | U26: CGG | W26: 2375000 | Y26: 2375000 | Z26: =Y26/T26 -> 1 | AA26: 2375000 | AC26: =S26-Y26 -> 0 | AD26: Completed
A27: 25 | B27: PROPOSED FENCING AND OTHER WORKS AT MASALANI MARKET | H27: Ijara | I27: Masalani | K27: =L27 -> ROADS,TRANSPORT AND PUBLIC WORKS | L27: ROADS,TRANSPORT AND PUBLIC WORKS | M27: =L27 -> ROADS,TRANSPORT AND PUBLIC WORKS | N27: 1st july 2022 | O27: 1st aug 2022 | P27: 30th june 2023 | Q27: 30th june 2023 | R27: 3040000 | S27: 3040000 | T27: 3040000 | U27: CGG | W27: 3040000 | Y27: 3040000 | Z27: =Y27/T27 -> 1 | AA27: 3040000 | AC27: =S27-Y27 -> 0 | AD27: Completed
A28: 26 | B28: PRPOSED RENOVATION OF WARDS AND WALK WAY AT IJARA SUB COUNTY OFFICE | H28: Ijara | I28: Ijara | K28: =L28 -> ROADS,TRANSPORT AND PUBLIC WORKS | L28: ROADS,TRANSPORT AND PUBLIC WORKS | M28: =L28 -> ROADS,TRANSPORT AND PUBLIC WORKS | N28: 1st july 2022 | O28: 1st aug 2022 | P28: 30th june 2023 | Q28: 30th june 2023 | R28: 3000000 | S28: 3000000 | T28: 3000000 | U28: CGG | W28: 3000000 | Y28: 3000000 | Z28: =Y28/T28 -> 1 | AA28: 3000000 | AC28: =S28-Y28 -> 0 | AD28: Completed
... A36: 34 | B36: RENOVATION FIRE STATION | H36: GarissaTownship | I36: Township | K36: =L36 -> LANDS,PHYSICAL PLANNING AND URBAN DEVELOPMENT | L36: LANDS,PHYSICAL PLANNING AND URBAN DEVELOPMENT | M36: =L36 -> LANDS,PHYSICAL PLANNING AND URBAN DEVELOPMENT | N36: 1st july 2022 | O36: 1st aug 2022 | P36: 30th june 2023 | Q36: 30th june 2023 | R36: 5985000 | S36: 5985000 | T36: 5985000 | U36: CGG | W36: 5985000 | Y36: 5985000 | Z36: =Y36/T36 -> 1 | AA36: 5985000 | AC36: =S36-Y36 -> 0 | AD36: Completed
A37: 35 | B37: ADC WATER PROJECT | H37: GarissaTownship | I37: Galbet | K37: =L37 -> WATER,ENVIRONMENT,CLIMATE CHANGE AND NATURAL RESOURCES | L37: WATER,ENVIRONMENT,CLIMATE CHANGE AND NATURAL RESOURCES | M37: =L37 -> WATER,ENVIRONMENT,CLIMATE CHANGE AND NATURAL RESOURCES | N37: 1st july 2023 | O37: 1st aug 2023 | P37: 30th june 2024 | Q37: 30th june 2024 | R37: 8383387.5 | S37: 8383387.5 | T37: 8383387.5 | U37: CGG | W37: 8383387.5 | Y37: 8383387.5 | Z37: =Y37/T37 -> 1 | AA37: =Y37 -> 8383387.5 | AC37: =S37-Y37 -> 0 | AD37: Completed
A38: 36 | B38: ADC WATER PROJECT | H38: GarissaTownship | I38: Galbet | K38: =L38 -> WATER,ENVIRONMENT,CLIMATE CHANGE AND NATURAL RESOURCES | L38: WATER,ENVIRONMENT,CLIMATE CHANGE AND NATURAL RESOURCES | M38: =L38 -> WATER,ENVIRONMENT,CLIMATE CHANGE AND NATURAL RESOURCES | N38: 1st july 2023 | O38: 1st aug 2023 | P38: 30th june 2024 | Q38: 30th june 2024 | R38: 9500000 | S38: 9500000 | T38: 9500000 | U38: CGG | W38: 9500000 | Y38: 9500000 | Z38: =Y38/T38 -> 1 | AA38: =Y38 -> 9500000 | AC38: =S38-Y38 -> 0 | AD38: Completed
A39: 37 | B39: MARAMTU WATER PROJECT | H39: GarissaTownship | I39: Iftin | K39: =L39 -> WATER,ENVIRONMENT,CLIMATE CHANGE AND NATURAL RESOURCES | L39: WATER,ENVIRONMENT,CLIMATE CHANGE AND NATURAL RESOURCES | M39: =L39 -> WATER,ENVIRONMENT,CLIMATE CHANGE AND NATURAL RESOURCES | N39: 1st july 2023 | O39: 1st aug 2023 | P39: 30th june 2024 | Q39: 30th june 2024 | R39: 13300000 | S39: 13300000 | T39: 13300000 | U39: CGG | W39: 13300000 | Y39: 13300000 | Z39: =Y39/T39 -> 1 | AA39: =Y39 -> 13300000 | AC39: =S39-Y39 -> 0 | AD39: Completed
A40: 38 | B40: MARAMTU WATER PROJECT | H40: GarissaTownship | I40: Iftin | K40: =L40 -> WATER,ENVIRONMENT,CLIMATE CHANGE AND NATURAL RESOURCES | L40: WATER,ENVIRONMENT,CLIMATE CHANGE AND NATURAL RESOURCES | M40: =L40 -> WATER,ENVIRONMENT,CLIMATE CHANGE AND NATURAL RESOURCES | N40: 1st july 2023 | O40: 1st aug 2023 | P40: 30th june 2024 | Q40: 30th june 2024 | R40: 12065000 | S40: 12065000 | T40: 12065000 | U40: CGG | W40: 12065000 | Y40: 12065000 | Z40: =Y40/T40 -> 1 | AA40: =Y40 -> 12065000 | AC40: =S40-Y40 -> 0 | AD40: Completed
A41: 39 | B41: EXTENSION OF PIPELINE IN MASALANI | H41: Ijara | I41: Masalani | K41: =L41 -> WATER,ENVIRONMENT,CLIMATE CHANGE AND NATURAL RESOURCES | L41: WATER,ENVIRONMENT,CLIMATE CHANGE AND NATURAL RESOURCES | M41: =L41 -> WATER,ENVIRONMENT,CLIMATE CHANGE AND NATURAL RESOURCES | N41: 1st july 2023 | O41: 1st aug 2023 | P41: 30th june 2024 | Q41: 30th june 2024 | R41: 4702500 | S41: 4702500 | T41: 4702500 | U41: CGG | W41: 4702500 | Y41: 4702500 | Z41: =Y41/T41 -> 1 | AA41: =Y41 -> 4702500 | AC41: =S41-Y41 -> 0 | AD41: Completed
A42: 40 | B42: SOLARIZATION AT SUQ MUQDI MARKET AND BULA MADINA | H42: GarissaTownship | I42: Township | K42: =L42 -> ROADS,TRANSPORT AND PUBLIC WORKS | L42: ROADS,TRANSPORT AND PUBLIC WORKS | M42: =L42 -> ROADS,TRANSPORT AND PUBLIC WORKS | N42: 1st july 2023 | O42: 1st aug 2023 | P42: 30th june 2024 | Q42: 30th june 2024 | R42: 12873700 | S42: 12873700 | T42: 12873700 | U42: CGG | W42: 12873700 | Y42: 12873700 | Z42: =Y42/T42 -> 1 | AA42: =Y42 -> 12873700 | AC42: =S42-Y42 -> 0 | AD42: Completed
A43: 41 | B43: DESILTING OF BULLA ABASS WATER PAN | H43: GarissaTownship | I43: Waberi | K43: =L43 -> WATER,ENVIRONMENT,CLIMATE CHANGE AND NATURAL RESOURCES | L43: WATER,ENVIRONMENT,CLIMATE CHANGE AND NATURAL RESOURCES | M43: =L43 -> WATER,ENVIRONMENT,CLIMATE CHANGE AND NATURAL RESOURCES | N43: 1st july 2023 | O43: 1st aug 2023 | P43: 30th june 2024 | Q43: 30th june 2024 | R43: 5880098.2 | S43: 5880098.2 | T43: 5880098.2 | U43: CGG | W43: 5880098.2 | Y43: 5880098.2 | Z43: =Y43/T43 -> 1 | AA43: =Y43 -> 5880098.2 | AC43: =S43-Y43 -> 0 | AD43: Completed
A44: 42 | B44: SUPPLY AND DELIVERY OF VETNARY DRUGS | H44: GarissaTownship | I44: Township | K44: =L44 -> AGRICULTURE,LIVESTOCK AND PASTORAL ECONOMY | L44: AGRICULTURE,LIVESTOCK AND PASTORAL ECONOMY | M44: =L44 -> AGRICULTURE,LIVESTOCK AND PASTORAL ECONOMY | N44: 1st july 2023 | O44: 1st aug 2023 | P44: 30th june 2024 | Q44: 30th june 2024 | R44: 3800000 | S44: 3800000 | T44: 3800000 | U44: CGG | W44: 3800000 | Y44: 3800000 | Z44: =Y44/T44 -> 1 | AA44: =Y44 -> 3800000 | AC44: =S44-Y44 -> 0 | AD44: Completed
A45: 43 | B45: EXTESION OF PIPELINE IN DAMAJALEWATER SUPPLY | H45: Dadaab | I45: Damajale | K45: =L45 -> WATER,ENVIRONMENT,CLIMATE CHANGE AND NATURAL RESOURCES | L45: WATER,ENVIRONMENT,CLIMATE CHANGE AND NATURAL RESOURCES | M45: =L45 -> WATER,ENVIRONMENT,CLIMATE CHANGE AND NATURAL RESOURCES | N45: 1st july 2023 | O45: 1st aug 2023 | P45: 30th june 2024 | Q45: 30th june 2024 | R45: 2318950 | S45: 2318950 | T45: 2318950 | U45: CGG | W45: 2318950 | Y45: 2318950 | Z45: =Y45/T45 -> 1 | AA45: =Y45 -> 2318950 | AC45: =S45-Y45 -> 0 | AD45: Completed
A46: 44 | B46: WATER PAN | H46: GarissaTownship | I46: Township | K46: =L46 -> WATER,ENVIRONMENT,CLIMATE CHANGE AND NATURAL RESOURCES | L46: WATER,ENVIRONMENT,CLIMATE CHANGE AND NATURAL RESOURCES | M46: =L46 -> WATER,ENVIRONMENT,CLIMATE CHANGE AND NATURAL RESOURCES | N46: 1st july 2023 | O46: 1st aug 2023 | P46: 30th june 2024 | Q46: 30th june 2024 | R46: 4560000 | S46: 4560000 | T46: 4560000 | U46: CGG | W46: 4560000 | Y46: 4560000 | Z46: =Y46/T46 -> 1 | AA46: =Y46 -> 4560000 | AC46: =S46-Y46 -> 0 | AD46: Completed
A47: 45 | B47: EXTENSION OF PIPELINE FOR QONE MODOGASHE PIPELINE | H47: Balambala | I47: Balambala | K47: =L47 -> WATER,ENVIRONMENT,CLIMATE CHANGE AND NATURAL RESOURCES | L47: WATER,ENVIRONMENT,CLIMATE CHANGE AND NATURAL RESOURCES | M47: =L47 -> WATER,ENVIRONMENT,CLIMATE CHANGE AND NATURAL RESOURCES | N47: 1st july 2023 | O47: 1st aug 2023 | P47: 30th june 2024 | Q47: 30th june 2024 | R47: 40000000 | S47: 40000000 | T47: 40000000 | U47: CGG | W47: 40000000 | Y47: 40000000 | Z47: =Y47/T47 -> 1 | AA47: =Y47 -> 40000000 | AC47: =S47-Y47 -> 0 | AD47: Completed
...

Sheet Summary List for Dashboard
A1: S/No. | B1: Project Name/Title | C1: Sub-County | D1: Ward | E1: Project Start Date/expected start date | F1: Expected Project Completion Date | G1: Actual Project Completion Date | H1: Estimated Project Cost (Kshs.) | I1: Project Status at the time of the Exercise (i.e Completed, Ongoing, Stalled)
A2: 1 | B2: ='Project Stocktaking Template'!B3 -> PROPOSED POWER UPGRADE AT GARISSA REFERAL HOSPITAL Waberi | C2: ='Project Stocktaking Template'!H3 -> GarissaTownship | D2: ='Project Stocktaking Template'!I3 -> Township | E2: ='Project Stocktaking Template'!O3 -> 1st aug 2022 | F2: ='Project Stocktaking Template'!P3 -> 30th june 2023 | G2: ='Project Stocktaking Template'!Q3 -> 30th june 2023 | H2: ='Project Stocktaking Template'!R3 -> 8550000 | I2: ='Project Stocktaking Template'!AD3 -> Completed
A3: 2 | B3: ='Project Stocktaking Template'!B4 -> PROPOSED DRILLINGAND EQUIPPING OF ADC FARM BOREHOLE | C3: ='Project Stocktaking Template'!H4 -> GarissaTownship | D3: ='Project Stocktaking Template'!I4 -> Galbet | E3: ='Project Stocktaking Template'!O4 -> 1st aug 2022 | F3: ='Project Stocktaking Template'!P4 -> 30th june 2023 | G3: ='Project Stocktaking Template'!Q4 -> 30th june 2023 | H3: ='Project Stocktaking Template'!R4 -> 9025000 | I3: ='Project Stocktaking Template'!AD4 -> Completed
A4: 3 | B4: ='Project Stocktaking Template'!B5 -> PROPOSED EQUIPING OF DERTU BOREHOLE | C4: ='Project Stocktaking Template'!H5 -> Dadaab | D4: ='Project Stocktaking Template'!I5 -> Dertu | E4: ='Project Stocktaking Template'!O5 -> 1st aug 2022 | F4: ='Project Stocktaking Template'!P5 -> 30th june 2023 | G4: ='Project Stocktaking Template'!Q5 -> 30th june 2023 | H4: ='Project Stocktaking Template'!R5 -> 4625407 | I4: ='Project Stocktaking Template'!AD5 -> Completed
A5: 4 | B5: ='Project Stocktaking Template'!B6 -> PROPOSED DRILLING OF DERTU BOREHOLE | C5: ='Project Stocktaking Template'!H6 -> Dadaab | D5: ='Project Stocktaking Template'!I6 -> Dertu | E5: ='Project Stocktaking Template'!O6 -> 1st aug 2022 | F5: ='Project Stocktaking Template'!P6 -> 30th june 2023 | G5: ='Project Stocktaking Template'!Q6 -> 30th june 2023 | H5: ='Project Stocktaking Template'!R6 -> 4693418 | I5: ='Project Stocktaking Template'!AD6 -> Completed
A6: 5 | B6: ='Project Stocktaking Template'!B7 -> PROPOSED DESILTING AT MOIT WATER PAN IJARA SUB COUNTY | C6: ='Project Stocktaking Template'!H7 -> Ijara | D6: ='Project Stocktaking Template'!I7 -> Ijara | E6: ='Project Stocktaking Template'!O7 -> 1st aug 2022 | F6: ='Project Stocktaking Template'!P7 -> 30th june 2023 | G6: ='Project Stocktaking Template'!Q7 -> 30th june 2023 | H6: ='Project Stocktaking Template'!R7 -> 3482500 | I6: ='Project Stocktaking Template'!AD7 -> Completed
A7: 6 | B7: ='Project Stocktaking Template'!B8 -> PROPOSED RENOVATION OF 4NO ECD CLASSROOM AT MAI PRIMARY | E7: ='Project Stocktaking Template'!O8 -> 1st aug 2022 | F7: ='Project Stocktaking Template'!P8 -> 30th june 2023 | G7: ='Project Stocktaking Template'!Q8 -> 30th june 2023 | H7: ='Project Stocktaking Template'!R8 -> 3100000 | I7: ='Project Stocktaking Template'!AD8 -> Completed
A8: 7 | B8: ='Project Stocktaking Template'!B9 -> PROPOSED RENOVATION OF 3NO. ECD CLASSROOMS CONSTRUCTION OF 2 STANCE PIT LATRINE RENOVATION OF 10K WATER TANK AT YATHRIB PRIMARY | C8: ='Project Stocktaking Template'!H9 -> GarissaTownship | D8: ='Project Stocktaking Template'!I9 -> Galbet | E8: ='Project Stocktaking Template'!O9 -> 1st aug 2022 | F8: ='Project Stocktaking Template'!P9 -> 30th june 2023 | G8: ='Project Stocktaking Template'!Q9 -> 30th june 2023 | H8: ='Project Stocktaking Template'!R9 -> 7200000 | I8: ='Project Stocktaking Template'!AD9 -> Completed
A9: 8 | B9: ='Project Stocktaking Template'!B10 -> PROPOSED RENOVATION OF 3NO. ECD CLASSROOMS CONSTRUCTION OF CHAINLINK FENCE AND HEAVY BUSH CLEARING2 STANCE PIT LATRINE RENOVATION K AT IFTIN PRIMARY | C9: ='Project Stocktaking Template'!H10 -> GarissaTownship | D9: ='Project Stocktaking Template'!I10 -> Iftin | E9: ='Project Stocktaking Template'!O10 -> 1st aug 2022 | F9: ='Project Stocktaking Template'!P10 -> 30th june 2023 | G9: ='Project Stocktaking Template'!Q10 -> 30th june 2023 | H9: ='Project Stocktaking Template'!R10 -> 5225000 | I9: ='Project Stocktaking Template'!AD10 -> Completed
A10: 9 | B10: ='Project Stocktaking Template'!B11 -> PROPOSED RENOVATION OF 3NO. ECD CLASSROOMS CONSTRUCTION OF 2 STANCE PIT LATRINE RENOVATION OF 10K WATER TANK AT AP GOODWISH TOWNSHIP WARD | C10: ='Project Stocktaking Template'!H11 -> GarissaTownship | D10: ='Project Stocktaking Template'!I11 -> Township | E10: ='Project Stocktaking Template'!O11 -> 1st aug 2022 | F10: ='Project Stocktaking Template'!P11 -> 30th june 2023 | G10: ='Project Stocktaking Template'!Q11 -> 30th june 2023 | H10: ='Project Stocktaking Template'!R11 -> 5225000 | I10: ='Project Stocktaking Template'!AD11 -> Completed
A11: 10 | B11: ='Project Stocktaking Template'!B12 -> PROPOSED RENOVATION 2NO ECD CLASSROOMS AND HEAVY BUSH CLEARING AND FENCING AT BULA MZURI PRIMARY | C11: ='Project Stocktaking Template'!H12 -> GarissaTownship | D11: ='Project Stocktaking Template'!I12 -> Waberi | E11: ='Project Stocktaking Template'!O12 -> 1st aug 2022 | F11: ='Project Stocktaking Template'!P12 -> 30th june 2023 | G11: ='Project Stocktaking Template'!Q12 -> 30th june 2023 | H11: ='Project Stocktaking Template'!R12 -> 5225000 | I11: ='Project Stocktaking Template'!AD12 -> Completed
A12: 11 | B12: ='Project Stocktaking Template'!B13 -> PRPOSED RENOVATION OF AND ROOFING AT WATER GARAGE GARISSA COUNTY | C12: ='Project Stocktaking Template'!H13 -> GarissaTownship | D12: ='Project Stocktaking Template'!I13 -> Township | E12: ='Project Stocktaking Template'!O13 -> 1st aug 2022 | F12: ='Project Stocktaking Template'!P13 -> 30th june 2023 | G12: ='Project Stocktaking Template'!Q13 -> 30th june 2023 | H12: ='Project Stocktaking Template'!R13 -> 7600000 | I12: ='Project Stocktaking Template'!AD13 -> Completed
A13: 12 | B13: ='Project Stocktaking Template'!B14 -> PRPOSED RENOVATION OF AND ROOFING AT WATER GARAGE GARISSA COUNTY | C13: ='Project Stocktaking Template'!H14 -> GarissaTownship | D13: ='Project Stocktaking Template'!I14 -> Township | E13: ='Project Stocktaking Template'!O14 -> 1st aug 2022 | F13: ='Project Stocktaking Template'!P14 -> 30th june 2023 | G13: ='Project Stocktaking Template'!Q14 -> 30th june 2023 | H13: ='Project Stocktaking Template'!R14 -> 7990000 | I13: ='Project Stocktaking Template'!AD14 -> Completed
A14: 13 | B14: ='Project Stocktaking Template'!B15 -> PROPOSED RENOVATION AND REFURBISHMENT OF DIRECTORS OFFICE | C14: ='Project Stocktaking Template'!H15 -> GarissaTownship | D14: ='Project Stocktaking Template'!I15 -> Township | E14: ='Project Stocktaking Template'!O15 -> 1st aug 2022 | F14: ='Project Stocktaking Template'!P15 -> 30th june 2023 | G14: ='Project Stocktaking Template'!Q15 -> 30th june 2023 | H14: ='Project Stocktaking Template'!R15 -> 1470000 | I14: ='Project Stocktaking Template'!AD15 -> Completed
A15: 14 | B15: ='Project Stocktaking Template'!B16 -> RENOVATION OF CEC OFFICES | C15: ='Project Stocktaking Template'!H16 -> GarissaTownship | D15: ='Project Stocktaking Template'!I16 -> Township | E15: ='Project Stocktaking Template'!O16 -> 1st aug 2022 | F15: ='Project Stocktaking Template'!P16 -> 30th june 2023 | G15: ='Project Stocktaking Template'!Q16 -> 30th june 2023 | H15: ='Project Stocktaking Template'!R16 -> 1000000 | I15: ='Project Stocktaking Template'!AD16 -> Completed
A16: 15 | B16: ='Project Stocktaking Template'!B17 -> PRPOSED RENOVATION OF AND ROOFING AT WATER GARAGE GARISSA COUNTY | C16: ='Project Stocktaking Template'!H17 -> GarissaTownship | D16: ='Project Stocktaking Template'!I17 -> Township | E16: ='Project Stocktaking Template'!O17 -> 1st aug 2022 | F16: ='Project Stocktaking Template'!P17 -> 30th june 2023 | G16: ='Project Stocktaking Template'!Q17 -> 30th june 2023 | H16: ='Project Stocktaking Template'!R17 -> 7990000 | I16: ='Project Stocktaking Template'!AD17 -> Completed
A17: 16 | B17: ='Project Stocktaking Template'!B18 -> PROPOSED REHABILATATION WORKS AT GAWASCO PIPE WORKS | C17: ='Project Stocktaking Template'!H18 -> GarissaTownship | D17: ='Project Stocktaking Template'!I18 -> Township | E17: ='Project Stocktaking Template'!O18 -> 1st aug 2022 | F17: ='Project Stocktaking Template'!P18 -> 30th june 2023 | G17: ='Project Stocktaking Template'!Q18 -> 30th june 2023 | H17: ='Project Stocktaking Template'!R18 -> 3895000 | I17: ='Project Stocktaking Template'!AD18 -> Completed
A18: 17 | B18: ='Project Stocktaking Template'!B19 -> PROPOSED RENOVATION AT DADAAB SUB COUNTY HOSPITAL | C18: ='Project Stocktaking Template'!H19 -> Dadaab | D18: ='Project Stocktaking Template'!I19 -> Dadaab | E18: ='Project Stocktaking Template'!O19 -> 1st aug 2022 | F18: ='Project Stocktaking Template'!P19 -> 30th june 2023 | G18: ='Project Stocktaking Template'!Q19 -> 30th june 2023 | H18: ='Project Stocktaking Template'!R19 -> 3325000 | I18: ='Project Stocktaking Template'!AD19 -> Completed
A19: 18 | B19: ='Project Stocktaking Template'!B20 -> PROPOSED RENOVATION OF 4NO ECD CLASSROOMS AT DIHLENUR PRIMARY SCHOOL | C19: ='Project Stocktaking Template'!H20 -> GarissaTownship | D19: ='Project Stocktaking Template'!I20 -> Township | E19: ='Project Stocktaking Template'!O20 -> 1st aug 2022 | F19: ='Project Stocktaking Template'!P20 -> 30th june 2023 | G19: ='Project Stocktaking Template'!Q20 -> 30th june 2023 | H19: ='Project Stocktaking Template'!R20 -> 4687852 | I19: ='Project Stocktaking Template'!AD20 -> Completed
... A615: 614 | B615: ='Project Stocktaking Template'!B616 -> MAINTAINACE OF MUHUMAD ABDI ROAD | C615: ='Project Stocktaking Template'!H616 -> Balambala | D615: ='Project Stocktaking Template'!I616 -> Balambala | E615: ='Project Stocktaking Template'!O616 -> 1st aug 2024 | F615: ='Project Stocktaking Template'!P616 -> 30th june 2025 | G615: ='Project Stocktaking Template'!Q616 -> 30th june 2025 | H615: ='Project Stocktaking Template'!R616 -> 3500000 | I615: ='Project Stocktaking Template'!AD616
A616: 615 | B616: =#REF! -> #REF! | C616: =#REF! -> #REF! | D616: =#REF! -> #REF! | E616: =#REF! -> #REF! | F616: =#REF! -> #REF! | G616: =#REF! -> #REF! | H616: =#REF! -> #REF! | I616: =#REF! -> #REF!
A617: 616 | B617: ='Project Stocktaking Template'!B617 -> MAINTAINANCE OF ACCESS ROAD | C617: ='Project Stocktaking Template'!H617 -> GarissaTownship | D617: ='Project Stocktaking Template'!I617 -> Township | E617: ='Project Stocktaking Template'!O617 -> 1st aug 2024 | F617: ='Project Stocktaking Template'!P617 -> 30th june 2025 | G617: ='Project Stocktaking Template'!Q617 -> 30th june 2025 | H617: ='Project Stocktaking Template'!R617 -> 4561116 | I617: ='Project Stocktaking Template'!AD617
A618: 617 | B618: ='Project Stocktaking Template'!B618 -> MAINTAINANCE OF BULA HODHAN | C618: ='Project Stocktaking Template'!H618 -> GarissaTownship | D618: ='Project Stocktaking Template'!I618 -> Township | E618: ='Project Stocktaking Template'!O618 -> 1st aug 2024 | F618: ='Project Stocktaking Template'!P618 -> 30th june 2025 | G618: ='Project Stocktaking Template'!Q618 -> 30th june 2025 | H618: ='Project Stocktaking Template'!R618 -> 4095288 | I618: ='Project Stocktaking Template'!AD618
A619: 618 | B619: ='Project Stocktaking Template'!B619 -> MAINTAINANCE OF BURA JUNCTION MANSABUBU | C619: ='Project Stocktaking Template'!H619 -> Fafi | D619: ='Project Stocktaking Template'!I619 -> Bura | E619: ='Project Stocktaking Template'!O619 -> 1st aug 2024 | F619: ='Project Stocktaking Template'!P619 -> 30th june 2025 | G619: ='Project Stocktaking Template'!Q619 -> 30th june 2025 | H619: ='Project Stocktaking Template'!R619 -> 4154640 | I619: ='Project Stocktaking Template'!AD619
A620: 619 | B620: ='Project Stocktaking Template'!B620 -> MAINTAINANCE OF DOBAL ALI HAYTAR ROAR | C620: ='Project Stocktaking Template'!H620 -> GarissaTownship | D620: ='Project Stocktaking Template'!I620 -> Township | E620: ='Project Stocktaking Template'!O620 -> 1st aug 2024 | F620: ='Project Stocktaking Template'!P620 -> 30th june 2025 | G620: ='Project Stocktaking Template'!Q620 -> 30th june 2025 | H620: ='Project Stocktaking Template'!R620 -> 4696724 | I620: ='Project Stocktaking Template'!AD620
A621: 620 | B621: ='Project Stocktaking Template'!B621 -> MAINTAINANCE OF FARM ACCESS ROAD | C621: ='Project Stocktaking Template'!H621 -> GarissaTownship | D621: ='Project Stocktaking Template'!I621 -> Township | E621: ='Project Stocktaking Template'!O621 -> 1st aug 2024 | F621: ='Project Stocktaking Template'!P621 -> 30th june 2025 | G621: ='Project Stocktaking Template'!Q621 -> 30th june 2025 | H621: ='Project Stocktaking Template'!R621 -> 2045260 | I621: ='Project Stocktaking Template'!AD621
A622: 621 | B622: ='Project Stocktaking Template'!B622 -> MAINTAINANCE OF FARM ACCESS ROAD | C622: ='Project Stocktaking Template'!H622 -> GarissaTownship | D622: ='Project Stocktaking Template'!I622 -> Township | E622: ='Project Stocktaking Template'!O622 -> 1st aug 2024 | F622: ='Project Stocktaking Template'!P622 -> 30th june 2025 | G622: ='Project Stocktaking Template'!Q622 -> 30th june 2025 | H622: ='Project Stocktaking Template'!R622 -> 450000 | I622: ='Project Stocktaking Template'!AD622
A623: 622 | B623: ='Project Stocktaking Template'!B623 -> MAINTAINANCE OF JUNCTION POINT BURBURIS ROAD | C623: ='Project Stocktaking Template'!H623 -> GarissaTownship | D623: ='Project Stocktaking Template'!I623 -> Galbet | E623: ='Project Stocktaking Template'!O623 -> 1st aug 2024 | F623: ='Project Stocktaking Template'!P623 -> 30th june 2025 | G623: ='Project Stocktaking Template'!Q623 -> 30th june 2025 | H623: ='Project Stocktaking Template'!R623 -> 4568916 | I623: ='Project Stocktaking Template'!AD623
A624: 623 | B624: ='Project Stocktaking Template'!B624 -> MAINTAINANCE OF LABASIGALE -WELHAR ROAD | C624: ='Project Stocktaking Template'!H624 -> GarissaTownship | D624: ='Project Stocktaking Template'!I624 -> Township | E624: ='Project Stocktaking Template'!O624 -> 1st aug 2024 | F624: ='Project Stocktaking Template'!P624 -> 30th june 2025 | G624: ='Project Stocktaking Template'!Q624 -> 30th june 2025 | H624: ='Project Stocktaking Template'!R624 -> 3758960 | I624: ='Project Stocktaking Template'!AD624
A625: 624 | B625: ='Project Stocktaking Template'!B625 -> MAINTAINANCE OF NULA NASIB ACCESS ROAD | C625: ='Project Stocktaking Template'!H625 -> GarissaTownship | D625: ='Project Stocktaking Template'!I625 -> Township | E625: ='Project Stocktaking Template'!O625 -> 1st aug 2024 | F625: ='Project Stocktaking Template'!P625 -> 30th june 2025 | G625: ='Project Stocktaking Template'!Q625 -> 30th june 2025 | H625: ='Project Stocktaking Template'!R625 -> 3765940 | I625: ='Project Stocktaking Template'!AD625
A626: 625 | B626: ='Project Stocktaking Template'!B626 -> MAINTAINANCE OF QABOBEY FARM ACCESS ROAD | C626: ='Project Stocktaking Template'!H626 -> GarissaTownship | D626: ='Project Stocktaking Template'!I626 -> Township | E626: ='Project Stocktaking Template'!O626 -> 1st aug 2024 | F626: ='Project Stocktaking Template'!P626 -> 30th june 2025 | G626: ='Project Stocktaking Template'!Q626 -> 30th june 2025 | H626: ='Project Stocktaking Template'!R626 -> 3718027.6 | I626: ='Project Stocktaking Template'!AD626
A627: 626 | B627: ='Project Stocktaking Template'!B627 -> MAINTAINANCE OF WABERI ACCESS ROAD | C627: ='Project Stocktaking Template'!H627 -> GarissaTownship | D627: ='Project Stocktaking Template'!I627 -> Waberi | E627: ='Project Stocktaking Template'!O627 -> 1st aug 2024 | F627: ='Project Stocktaking Template'!P627 -> 30th june 2025 | G627: ='Project Stocktaking Template'!Q627 -> 30th june 2025 | H627: ='Project Stocktaking Template'!R627 -> 4100234 | I627: ='Project Stocktaking Template'!AD627
A628: 627 | B628: ='Project Stocktaking Template'!B628 -> MAINTAINCE OF BULA GAME ACCESS ROAD | C628: ='Project Stocktaking Template'!H628 -> GarissaTownship | D628: ='Project Stocktaking Template'!I628 -> Iftin | E628: ='Project Stocktaking Template'!O628 -> 1st aug 2024 | F628: ='Project Stocktaking Template'!P628 -> 30th june 2025 | G628: ='Project Stocktaking Template'!Q628 -> 30th june 2025 | H628: ='Project Stocktaking Template'!R628 -> 4465116 | I628: ='Project Stocktaking Template'!AD628
... A868: 867 | B868: ='Project Stocktaking Template'!B868 -> RENOVATION OF ECONOMIC PLANNING OFFICES | C868: ='Project Stocktaking Template'!H868 -> GarissaTownship | D868: ='Project Stocktaking Template'!I868 -> Township | E868: ='Project Stocktaking Template'!O868 -> 1st aug 2024 | F868: ='Project Stocktaking Template'!P868 -> 30th june 2025 | G868: ='Project Stocktaking Template'!Q868 -> 30th june 2025 | H868: ='Project Stocktaking Template'!R868 -> 2752600 | I868: ='Project Stocktaking Template'!AD868

Sheet Formula Sheet
B3: GOK
B4: Development Partner
B5: GOK & Development Partner
B8: Yes
B9: No
B12: Compete
B13: Cancel
B14: Defer
B16: Completed
B17: Ongoing
B18: Stalled

Sheet Sheet1
A10: Report prepared by:
A11: Designation:
A12: Signature:
A13: Date:
A16: Report approved by:
A17: Designation:
A18: Signature:
A19: Date:

Sheet Departments
A1: Department_ID | B1: Department_Name | C1: Directorate_Name
B2: WATER,ENVIRONMENT,CLIMATE CHANGE AND NATURAL RESOURCES | C2: 1. WATER 2. ENVIRONMENT 3. CLIMATE CHANGE 4. NATURAL RESOURCES
B3: AGRICULTURE,LIVESTOCK AND PASTORAL ECONOMY | C3: 1. AGRICULTURE 2. LIVESTOCK 3. PASTORAL ECONOMY
B4: COUNTY AFFAIRS,PUBLIC SERVICES AND INTERGOVERNMENTAL RELATIONS | C4: 1. COUNTY AFFAIRS 2. PUBLIC SERVICES 3. INTERGOVERNMENTAL RELATIONS
B5: TRADE,INVESTMENT AND ENTERPRISE DEVELOPMENT | C5: 1. TRADE 2. INVESTMENT 3. ENTERPRISE DEVELOPMENT
B6: CULTURE,GENDER,YOUTH AND SPORTS | C6: 1. CULTURE 2. GENDER 3. YOUTH AND SPORTS
B7: ROADS,TRANSPORT AND PUBLIC WORKS | C7: 1. ROADS 2. TRANSPORT 3. PUBLIC WORKS
B8: LANDS,PHYSICAL PLANNING AND URBAN DEVELOPMENT | C8: 1. LANDS 2. PHYSICAL PLANNING 3. URBAN DEVELOPMENT
B9: EDUCATION,INFORMATION AND ICT | C9: 1. ECDE 2. Vocational 3. INFORMATION and Library Services 4. ICT
B10: HEALTH | C10: HEALTH
B11: FINANCE AND ECONOMIC PLANNING | C11: 1. FINANCE 2. ECONOMIC PLANNING

Sheet SubcountyLookup
A1: Sub-County | B1: Wards | C1: Wards Separate | F1: Villages | L1: G | M1: H
A2: Garissa Township | B2: Waberi, Galbet, Township, Iftin | C2: Waberi | F2: BALAMBALA | G2: BALAMBALA
A3: Balambala | B3: Balambala, Danyere, Jarajara, Saka, Sankuri | C3: Galbet | F3: BURADANSA
A4: Ijara | B4: Hulugho, Sangailu, Ijara, Masalani | C4: Township | F4: DUJIS
A5: Fafi | B5: Bura, Dekaharia, Jarajila, Fafi, Nanighi | C5: Iftin | F5: SHIDLE
A6: Dadaab | B6: Dertu, Dadaab, Labasigale, Damajale, Liboi, Abakaile | C6: Balambala | F6: JARAJARA
A7: Lagdera | B7: Modogashe, Benane, Goreale, Maalimin, Sabena, Baraki | C7: Danyere | F7: KONE
C8: Jarajara | F8: OHIO
C9: Saka | F9: ABDIGAB
C10: Sankuri | F10: ASHADIN
C11: Hulugho | F11: DANYERE
C12: Sangailu | F12: DANYERE
C13: Ijara | F13: DANYERE
C14: Masalani | F14: URGAAD
C15: Bura | F15: LIBAHLOW
C16: Dekaharia | F16: DOGOB
C17: Jarajila | F17: MUDEY
C18: Fafi | F18: MUDEY
C19: Nanighi | F19: SAKA
... C27: Benane | F27: SAKA JUNCTION
C28: Goreale
C29: Maalimin
C30: Sabena | F30: DADAAB | G30: DADAAB
C31: Baraki | F31: ABAKAILE
F32: ALANGO ARBA
F33: ALIKUNE
F34: DAGAHALEY
F35: KUMAHUMATO
F36: LABISIGALE
F37: WELHAR
F38: MATHAGIS
F39: DERTU
F40: DAMAJALE
F41: KOKAR
F42: KULAN
F43: LIBOI
F44: HARHAR
F48: FAFI | G48: FAFI
F49: BURA
F50: JAMBELE
...
